2024-07-09 15:45:05,557 ERROR: Exception on /upload [POST] [in /home/bruno/.local/lib/python3.10/site-packages/flask/app.py:838]
Traceback (most recent call last):
  File "/home/bruno/.local/lib/python3.10/site-packages/flask/app.py", line 1473, in wsgi_app
    response = self.full_dispatch_request()
  File "/home/bruno/.local/lib/python3.10/site-packages/flask/app.py", line 882, in full_dispatch_request
    rv = self.handle_user_exception(e)
  File "/home/bruno/.local/lib/python3.10/site-packages/flask/app.py", line 880, in full_dispatch_request
    rv = self.dispatch_request()
  File "/home/bruno/.local/lib/python3.10/site-packages/flask/app.py", line 865, in dispatch_request
    return self.ensure_sync(self.view_functions[rule.endpoint])(**view_args)  # type: ignore[no-any-return]
  File "/mnt/c/Users/bruno/Documents/1_Programming/Github Projects/falafel/falafel/app.py", line 154, in upload_file
    file.save(filepath)
  File "/home/bruno/.local/lib/python3.10/site-packages/werkzeug/datastructures/file_storage.py", line 125, in save
    dst = open(dst, "wb")
FileNotFoundError: [Errno 2] No such file or directory: 'uploads/Dog.jpg'
2024-07-09 15:45:06,406 ERROR: Exception on /upload [POST] [in /home/bruno/.local/lib/python3.10/site-packages/flask/app.py:838]
Traceback (most recent call last):
  File "/home/bruno/.local/lib/python3.10/site-packages/flask/app.py", line 1473, in wsgi_app
    response = self.full_dispatch_request()
  File "/home/bruno/.local/lib/python3.10/site-packages/flask/app.py", line 882, in full_dispatch_request
    rv = self.handle_user_exception(e)
  File "/home/bruno/.local/lib/python3.10/site-packages/flask/app.py", line 880, in full_dispatch_request
    rv = self.dispatch_request()
  File "/home/bruno/.local/lib/python3.10/site-packages/flask/app.py", line 865, in dispatch_request
    return self.ensure_sync(self.view_functions[rule.endpoint])(**view_args)  # type: ignore[no-any-return]
  File "/mnt/c/Users/bruno/Documents/1_Programming/Github Projects/falafel/falafel/app.py", line 154, in upload_file
    file.save(filepath)
  File "/home/bruno/.local/lib/python3.10/site-packages/werkzeug/datastructures/file_storage.py", line 125, in save
    dst = open(dst, "wb")
FileNotFoundError: [Errno 2] No such file or directory: 'uploads/Dog.jpg'
2024-07-09 15:45:07,327 ERROR: Exception on /upload [POST] [in /home/bruno/.local/lib/python3.10/site-packages/flask/app.py:838]
Traceback (most recent call last):
  File "/home/bruno/.local/lib/python3.10/site-packages/flask/app.py", line 1473, in wsgi_app
    response = self.full_dispatch_request()
  File "/home/bruno/.local/lib/python3.10/site-packages/flask/app.py", line 882, in full_dispatch_request
    rv = self.handle_user_exception(e)
  File "/home/bruno/.local/lib/python3.10/site-packages/flask/app.py", line 880, in full_dispatch_request
    rv = self.dispatch_request()
  File "/home/bruno/.local/lib/python3.10/site-packages/flask/app.py", line 865, in dispatch_request
    return self.ensure_sync(self.view_functions[rule.endpoint])(**view_args)  # type: ignore[no-any-return]
  File "/mnt/c/Users/bruno/Documents/1_Programming/Github Projects/falafel/falafel/app.py", line 154, in upload_file
    file.save(filepath)
  File "/home/bruno/.local/lib/python3.10/site-packages/werkzeug/datastructures/file_storage.py", line 125, in save
    dst = open(dst, "wb")
FileNotFoundError: [Errno 2] No such file or directory: 'uploads/Dog.jpg'
