2024-07-10 12:17:15,728 ERROR: Exception on /model [GET] [in /home/bruno/.local/lib/python3.10/site-packages/flask/app.py:838]
Traceback (most recent call last):
  File "/home/bruno/.local/lib/python3.10/site-packages/flask/app.py", line 1473, in wsgi_app
    response = self.full_dispatch_request()
  File "/home/bruno/.local/lib/python3.10/site-packages/flask/app.py", line 882, in full_dispatch_request
    rv = self.handle_user_exception(e)
  File "/home/bruno/.local/lib/python3.10/site-packages/flask/app.py", line 880, in full_dispatch_request
    rv = self.dispatch_request()
  File "/home/bruno/.local/lib/python3.10/site-packages/flask/app.py", line 865, in dispatch_request
    return self.ensure_sync(self.view_functions[rule.endpoint])(**view_args)  # type: ignore[no-any-return]
  File "/mnt/c/Users/bruno/Documents/1_Programming/Github Projects/falafel/falafel/app.py", line 205, in model_info
    acc_fig.add_trace(go.Scatter(y=history['accuracy'], name="Train Accuracy"))
KeyError: 'accuracy'
2024-07-10 12:17:15,902 ERROR: Exception on /model [GET] [in /home/bruno/.local/lib/python3.10/site-packages/flask/app.py:838]
Traceback (most recent call last):
  File "/home/bruno/.local/lib/python3.10/site-packages/flask/app.py", line 1473, in wsgi_app
    response = self.full_dispatch_request()
  File "/home/bruno/.local/lib/python3.10/site-packages/flask/app.py", line 882, in full_dispatch_request
    rv = self.handle_user_exception(e)
  File "/home/bruno/.local/lib/python3.10/site-packages/flask/app.py", line 880, in full_dispatch_request
    rv = self.dispatch_request()
  File "/home/bruno/.local/lib/python3.10/site-packages/flask/app.py", line 865, in dispatch_request
    return self.ensure_sync(self.view_functions[rule.endpoint])(**view_args)  # type: ignore[no-any-return]
  File "/mnt/c/Users/bruno/Documents/1_Programming/Github Projects/falafel/falafel/app.py", line 205, in model_info
    acc_fig.add_trace(go.Scatter(y=history['accuracy'], name="Train Accuracy"))
KeyError: 'accuracy'
2024-07-10 12:17:16,133 ERROR: Exception on /model [GET] [in /home/bruno/.local/lib/python3.10/site-packages/flask/app.py:838]
Traceback (most recent call last):
  File "/home/bruno/.local/lib/python3.10/site-packages/flask/app.py", line 1473, in wsgi_app
    response = self.full_dispatch_request()
  File "/home/bruno/.local/lib/python3.10/site-packages/flask/app.py", line 882, in full_dispatch_request
    rv = self.handle_user_exception(e)
  File "/home/bruno/.local/lib/python3.10/site-packages/flask/app.py", line 880, in full_dispatch_request
    rv = self.dispatch_request()
  File "/home/bruno/.local/lib/python3.10/site-packages/flask/app.py", line 865, in dispatch_request
    return self.ensure_sync(self.view_functions[rule.endpoint])(**view_args)  # type: ignore[no-any-return]
  File "/mnt/c/Users/bruno/Documents/1_Programming/Github Projects/falafel/falafel/app.py", line 205, in model_info
    acc_fig.add_trace(go.Scatter(y=history['accuracy'], name="Train Accuracy"))
KeyError: 'accuracy'
2024-07-10 12:17:16,341 ERROR: Exception on /model [GET] [in /home/bruno/.local/lib/python3.10/site-packages/flask/app.py:838]
Traceback (most recent call last):
  File "/home/bruno/.local/lib/python3.10/site-packages/flask/app.py", line 1473, in wsgi_app
    response = self.full_dispatch_request()
  File "/home/bruno/.local/lib/python3.10/site-packages/flask/app.py", line 882, in full_dispatch_request
    rv = self.handle_user_exception(e)
  File "/home/bruno/.local/lib/python3.10/site-packages/flask/app.py", line 880, in full_dispatch_request
    rv = self.dispatch_request()
  File "/home/bruno/.local/lib/python3.10/site-packages/flask/app.py", line 865, in dispatch_request
    return self.ensure_sync(self.view_functions[rule.endpoint])(**view_args)  # type: ignore[no-any-return]
  File "/mnt/c/Users/bruno/Documents/1_Programming/Github Projects/falafel/falafel/app.py", line 205, in model_info
    acc_fig.add_trace(go.Scatter(y=history['accuracy'], name="Train Accuracy"))
KeyError: 'accuracy'
2024-07-10 12:17:16,547 ERROR: Exception on /model [GET] [in /home/bruno/.local/lib/python3.10/site-packages/flask/app.py:838]
Traceback (most recent call last):
  File "/home/bruno/.local/lib/python3.10/site-packages/flask/app.py", line 1473, in wsgi_app
    response = self.full_dispatch_request()
  File "/home/bruno/.local/lib/python3.10/site-packages/flask/app.py", line 882, in full_dispatch_request
    rv = self.handle_user_exception(e)
  File "/home/bruno/.local/lib/python3.10/site-packages/flask/app.py", line 880, in full_dispatch_request
    rv = self.dispatch_request()
  File "/home/bruno/.local/lib/python3.10/site-packages/flask/app.py", line 865, in dispatch_request
    return self.ensure_sync(self.view_functions[rule.endpoint])(**view_args)  # type: ignore[no-any-return]
  File "/mnt/c/Users/bruno/Documents/1_Programming/Github Projects/falafel/falafel/app.py", line 205, in model_info
    acc_fig.add_trace(go.Scatter(y=history['accuracy'], name="Train Accuracy"))
KeyError: 'accuracy'
2024-07-10 12:17:16,728 ERROR: Exception on /model [GET] [in /home/bruno/.local/lib/python3.10/site-packages/flask/app.py:838]
Traceback (most recent call last):
  File "/home/bruno/.local/lib/python3.10/site-packages/flask/app.py", line 1473, in wsgi_app
    response = self.full_dispatch_request()
  File "/home/bruno/.local/lib/python3.10/site-packages/flask/app.py", line 882, in full_dispatch_request
    rv = self.handle_user_exception(e)
  File "/home/bruno/.local/lib/python3.10/site-packages/flask/app.py", line 880, in full_dispatch_request
    rv = self.dispatch_request()
  File "/home/bruno/.local/lib/python3.10/site-packages/flask/app.py", line 865, in dispatch_request
    return self.ensure_sync(self.view_functions[rule.endpoint])(**view_args)  # type: ignore[no-any-return]
  File "/mnt/c/Users/bruno/Documents/1_Programming/Github Projects/falafel/falafel/app.py", line 205, in model_info
    acc_fig.add_trace(go.Scatter(y=history['accuracy'], name="Train Accuracy"))
KeyError: 'accuracy'
2024-07-10 12:17:16,900 ERROR: Exception on /model [GET] [in /home/bruno/.local/lib/python3.10/site-packages/flask/app.py:838]
Traceback (most recent call last):
  File "/home/bruno/.local/lib/python3.10/site-packages/flask/app.py", line 1473, in wsgi_app
    response = self.full_dispatch_request()
  File "/home/bruno/.local/lib/python3.10/site-packages/flask/app.py", line 882, in full_dispatch_request
    rv = self.handle_user_exception(e)
  File "/home/bruno/.local/lib/python3.10/site-packages/flask/app.py", line 880, in full_dispatch_request
    rv = self.dispatch_request()
  File "/home/bruno/.local/lib/python3.10/site-packages/flask/app.py", line 865, in dispatch_request
    return self.ensure_sync(self.view_functions[rule.endpoint])(**view_args)  # type: ignore[no-any-return]
  File "/mnt/c/Users/bruno/Documents/1_Programming/Github Projects/falafel/falafel/app.py", line 205, in model_info
    acc_fig.add_trace(go.Scatter(y=history['accuracy'], name="Train Accuracy"))
KeyError: 'accuracy'
2024-07-10 12:17:17,069 ERROR: Exception on /model [GET] [in /home/bruno/.local/lib/python3.10/site-packages/flask/app.py:838]
Traceback (most recent call last):
  File "/home/bruno/.local/lib/python3.10/site-packages/flask/app.py", line 1473, in wsgi_app
    response = self.full_dispatch_request()
  File "/home/bruno/.local/lib/python3.10/site-packages/flask/app.py", line 882, in full_dispatch_request
    rv = self.handle_user_exception(e)
  File "/home/bruno/.local/lib/python3.10/site-packages/flask/app.py", line 880, in full_dispatch_request
    rv = self.dispatch_request()
  File "/home/bruno/.local/lib/python3.10/site-packages/flask/app.py", line 865, in dispatch_request
    return self.ensure_sync(self.view_functions[rule.endpoint])(**view_args)  # type: ignore[no-any-return]
  File "/mnt/c/Users/bruno/Documents/1_Programming/Github Projects/falafel/falafel/app.py", line 205, in model_info
    acc_fig.add_trace(go.Scatter(y=history['accuracy'], name="Train Accuracy"))
KeyError: 'accuracy'
2024-07-10 12:17:17,374 ERROR: Exception on /model [GET] [in /home/bruno/.local/lib/python3.10/site-packages/flask/app.py:838]
Traceback (most recent call last):
  File "/home/bruno/.local/lib/python3.10/site-packages/flask/app.py", line 1473, in wsgi_app
    response = self.full_dispatch_request()
  File "/home/bruno/.local/lib/python3.10/site-packages/flask/app.py", line 882, in full_dispatch_request
    rv = self.handle_user_exception(e)
  File "/home/bruno/.local/lib/python3.10/site-packages/flask/app.py", line 880, in full_dispatch_request
    rv = self.dispatch_request()
  File "/home/bruno/.local/lib/python3.10/site-packages/flask/app.py", line 865, in dispatch_request
    return self.ensure_sync(self.view_functions[rule.endpoint])(**view_args)  # type: ignore[no-any-return]
  File "/mnt/c/Users/bruno/Documents/1_Programming/Github Projects/falafel/falafel/app.py", line 205, in model_info
    acc_fig.add_trace(go.Scatter(y=history['accuracy'], name="Train Accuracy"))
KeyError: 'accuracy'
2024-07-10 12:17:17,511 ERROR: Exception on /model [GET] [in /home/bruno/.local/lib/python3.10/site-packages/flask/app.py:838]
Traceback (most recent call last):
  File "/home/bruno/.local/lib/python3.10/site-packages/flask/app.py", line 1473, in wsgi_app
    response = self.full_dispatch_request()
  File "/home/bruno/.local/lib/python3.10/site-packages/flask/app.py", line 882, in full_dispatch_request
    rv = self.handle_user_exception(e)
  File "/home/bruno/.local/lib/python3.10/site-packages/flask/app.py", line 880, in full_dispatch_request
    rv = self.dispatch_request()
  File "/home/bruno/.local/lib/python3.10/site-packages/flask/app.py", line 865, in dispatch_request
    return self.ensure_sync(self.view_functions[rule.endpoint])(**view_args)  # type: ignore[no-any-return]
  File "/mnt/c/Users/bruno/Documents/1_Programming/Github Projects/falafel/falafel/app.py", line 205, in model_info
    acc_fig.add_trace(go.Scatter(y=history['accuracy'], name="Train Accuracy"))
KeyError: 'accuracy'
